[2021-09-02 21:38:37,559] {taskinstance.py:876} INFO - Dependencies all met for <TaskInstance: elasticsearch_dag.connections_to_es 2021-09-02T21:35:44.881479+00:00 [queued]>
[2021-09-02 21:38:37,612] {taskinstance.py:876} INFO - Dependencies all met for <TaskInstance: elasticsearch_dag.connections_to_es 2021-09-02T21:35:44.881479+00:00 [queued]>
[2021-09-02 21:38:37,613] {taskinstance.py:1067} INFO - 
--------------------------------------------------------------------------------
[2021-09-02 21:38:37,617] {taskinstance.py:1068} INFO - Starting attempt 3 of 3
[2021-09-02 21:38:37,617] {taskinstance.py:1069} INFO - 
--------------------------------------------------------------------------------
[2021-09-02 21:38:37,632] {taskinstance.py:1087} INFO - Executing <Task(PostgresToElasticOperator): connections_to_es> on 2021-09-02T21:35:44.881479+00:00
[2021-09-02 21:38:37,663] {standard_task_runner.py:52} INFO - Started process 47868 to run task
[2021-09-02 21:38:37,677] {standard_task_runner.py:76} INFO - Running: ['airflow', 'tasks', 'run', 'elasticsearch_dag', 'connections_to_es', '2021-09-02T21:35:44.881479+00:00', '--job-id', '91', '--pool', 'default_pool', '--raw', '--subdir', 'DAGS_FOLDER/elasticsearch_dag.py', '--cfg-path', '/tmp/tmp6c_fczqj', '--error-file', '/tmp/tmp88ca11y3']
[2021-09-02 21:38:37,678] {standard_task_runner.py:77} INFO - Job 91: Subtask connections_to_es
[2021-09-02 21:38:37,962] {logging_mixin.py:104} INFO - Running <TaskInstance: elasticsearch_dag.connections_to_es 2021-09-02T21:35:44.881479+00:00 [running]> on host airflowvm
[2021-09-02 21:38:38,313] {taskinstance.py:1280} INFO - Exporting the following env vars:
AIRFLOW_CTX_DAG_OWNER=airflow
AIRFLOW_CTX_DAG_ID=elasticsearch_dag
AIRFLOW_CTX_TASK_ID=connections_to_es
AIRFLOW_CTX_EXECUTION_DATE=2021-09-02T21:35:44.881479+00:00
AIRFLOW_CTX_DAG_RUN_ID=manual__2021-09-02T21:35:44.881479+00:00
[2021-09-02 21:38:38,330] {base.py:69} INFO - Using connection to: id: elasticsearch_default. Host: localhost, Port: 9200, Schema: http, Login: None, Password: None, extra: {}
[2021-09-02 21:38:38,377] {base.py:69} INFO - Using connection to: id: ***_default. Host: localhost, Port: 5432, Schema: , Login: ***, Password: ***, extra: {'cursor': 'realdictcursor'}
[2021-09-02 21:38:38,410] {taskinstance.py:1481} ERROR - Task failed with exception
Traceback (most recent call last):
  File "/home/airflow/sandbox/lib/python3.8/site-packages/airflow/models/taskinstance.py", line 1137, in _run_raw_task
    self._prepare_and_execute_task_with_callbacks(context, task)
  File "/home/airflow/sandbox/lib/python3.8/site-packages/airflow/models/taskinstance.py", line 1311, in _prepare_and_execute_task_with_callbacks
    result = self._execute_task(context, task_copy)
  File "/home/airflow/sandbox/lib/python3.8/site-packages/airflow/models/taskinstance.py", line 1341, in _execute_task
    result = task_copy.execute(context=context)
  File "/home/airflow/airflow/plugins/elasticsearch_plugin/operators/postgres_to_elastic.py", line 28, in execute
    doc = json.dump(row, indent=2)
TypeError: dump() missing 1 required positional argument: 'fp'
[2021-09-02 21:38:38,416] {taskinstance.py:1524} INFO - Marking task as FAILED. dag_id=elasticsearch_dag, task_id=connections_to_es, execution_date=20210902T213544, start_date=20210902T213837, end_date=20210902T213838
[2021-09-02 21:38:38,504] {local_task_job.py:151} INFO - Task exited with return code 1
